Workbook

Sheet F4
B1: Nume Proiect / Project Title:Proiectare Si Executie Lucrari Pentru Obiectivul De Investitii: Sediu Nou Pentru Spitalul De Urgenta Prof. Dr. Dimitrie Gerota
B2: Numar Proiect / Project Number: 2S/2024
B3: Data / Date: Septembrie 2025
B4: Beneficiar / Beneficiary: Spitalul de Urgență ”Prof. Dr. Dimitrie Gerota”
B5: Proiectant General / General Designer: Asocierea CCN ALTYAPI YATIRIMLARI VE INSAAT A.S. - CCN YATIRIM HOLDING A.S.
C7: LISTA ECHIPAMENTE | D7: EQUIPMENT LIST
C8: LUCRARI DE INSTALATII SANITARE | D8: SANITARY INSTALLATIONS WORKS
B9: Nr. | C9: Denumirea | D9: Name | E9: U.M. | F9: Cantitate Quantity | G9: Pret unitar (fara TVA) / Unit Price (without VAT) - Lei - | H9: Valoarea (fara TVA) / Value (without VAT) - Lei - | I9: Nr. Fisa tehnica | L9: INDICATOR SCHEMA FUNCTIONALA | M9: AMPLASARE / DETALII
B10: 0 | C10: 1 | D10: 1 | E10: 2 | F10: 3 | G10: 4 | H10: 5 = 3 X 4 | I10: 6 | L10: 7 | M10: 8
B11: Utilaje, echipamente tehnologice si functionale care necesita montaj / Cost of Machinery & equipment that requires assembly
B12: 8 | C12: Statie clorinare, recirculare si tratare UV pentru rezerva hidranti - Cod schema F16 | D12: Chlorination, water recirculation and UV Water Treatment Plant for hydrants water tank - Scheme code F16 | E12: buc./pcs | F12: 1 | H12: =F12*G12 -> 0 | I12: Fisa tehnica nr 08 | M12: subsol 3
B13: 9 | C13: Statie clorinare, recirculare si tratare UV pentru rezerva sprinklere - Cod schema F17 | D13: Chlorination, water recirculation and UV Water Treatment Plant for sprinkler water tank - Scheme code F17 | E13: buc./pcs | F13: 1 | H13: =F13*G13 -> 0 | I13: Fisa tehnica nr 09 | M13: subsol 3
B14: 15 | C14: Statie dedurizare duplex pentru turnuri de racire - Cod schema W16 | D14: Duplex type water softening unit for domestic water - Scheme code W16 | E14: buc./pcs | F14: 1 | H14: 0 | I14: Fisa tehnica nr 15 | L14: W16
B15: 16 | C15: Statie dedurizare duplex pentru apa dedurizata - Cod schema W12 | D15: Duplex type water softening unit for softened water tank - Scheme code W12 | E15: buc./pcs | F15: 1 | H15: 0 | I15: Fisa tehnica nr 16 | L15: W12
B16: 34 | C16: Sterilizator UV apa rece potabila | D16: UV sterilizer for potable cold water | E16: buc./pcs | F16: 1 | H16: 0 | I16: Fisa tehnica nr 34 | M16: bazin put forat
B17: 35 | C17: Filtru cu carbon activ tip duplex - Cod schema W25 | D17: Duplex type activated carbon filter - Scheme code W25 | E17: buc./pcs | F17: 1 | H17: 0 | I17: Fisa tehnica nr 35 | L17: W25
B18: 36 | C18: Statie osmoza inversa - Cod schema W24 | D18: Reverse osmosis unit - Scheme code W24 | E18: buc./pcs | F18: 1 | H18: 0 | I18: Fisa tehnica nr 36 | L18: W24
B19: 37 | C19: Sistem dozare substante dezinfectante pentru apa potabila | D19: Dosing system for disinfectant substances for potable water | E19: buc./pcs | F19: 1 | H19: 0 | I19: Fisa tehnica nr 37 | M19: rezervor apa put forat
B20: 38 | C20: Sistem dozare substante floculante pentru apa de adaos instalatii HVAC | D20: Dosing system for flocculant substances for HVAC systems makeup water | E20: buc./pcs | F20: 1 | H20: 0 | I20: Fisa tehnica nr 38 | M20: turni racire
B21: 39 | C21: Sistem dozare substante anti-alge pentru apa de adaos turnuri de racire | D21: Dosing system for anti-algae substances for cooling towers makeup water | E21: buc./pcs | F21: 1 | H21: 0 | I21: Fisa tehnica nr 39 | M21: turni racire
B22: 40 | C22: Sistem dozare substante anti-coroziune si anti-depuneri pentru apa | D22: Dosing system for anti-corrosion and anti-scaling substances for water | E22: buc./pcs | F22: 1 | H22: 0 | I22: Fisa tehnica nr 40 | M22: bazin put forat
B23: 41 | C23: Unitate de dozare pentru monocloramina | D23: Dosing unit for monochloramine | E23: buc./pcs | F23: 2 | H23: 0 | I23: Fisa tehnica nr 41 | M23: rezervor beton apa potabila
B24: 42 | C24: Unitate de dozare pentru clor pentru sistem de recirculare bazine apa | D24: Dosing unit for chlorine for recirculation system of potable water tanks | E24: buc./pcs | F24: 2 | H24: 0 | I24: Fisa tehnica nr 42 | M24: rezervor beton apa potabila
B25: 59 | C25: Filtru de nisip - Cod schema W26 | D25: Sand filter - Scheme code W26 | E25: buc./pcs | F25: 1 | H25: 0 | I25: Fisa tehnica nr 59 | L25: W26 | M25: CAMERA TEHNICA S3
B26: 60 | C26: Statie dedurizare duplex pentru puturile forate - Cod schema W34 | D26: Duplex type water softening unit for well water - Scheme code W34 | E26: buc./pcs | F26: 1 | H26: 0 | I26: Fisa tehnica nr 60 | L26: W34 | M26: CAMERA TEHNICA S3
B27: 61 | C27: Sistem dozare clor - Cod schema W36 | D27: Chlorine dosing system - Scheme code W36 | E27: buc./pcs | F27: 1 | H27: 0 | I27: Fisa tehnica nr 61 | L27: W36 | M27: CAMERA TEHNICA S3
B28: 63 | C28: Pompa recirculare bazin put forat - Cod schema W37 | D28: Drilled well pool recirculation pump - Scheme code W37 | E28: buc./pcs | F28: 1 | H28: 0 | I28: Fisa tehnica nr 63 | L28: W37 | M28: CAMERA TEHNICA S3
B29: 71 | C29: Filtru impuritati automat cu sita - Cod schema W35 | D29: Automatic impurity filter with a screen - Scheme code W35 | E29: buc./pcs | F29: 1 | H29: 0 | I29: Fisa tehnica nr 71 | L29: W35
B30: TOTAL Utilaje, echipamente tehnologice si functionale care necesita montaj | D30: TOTAL Cost of Machinery & equipment that requires assembly | H30: =SUBTOTAL(9,H14:H24) -> 0
B31: Utilaje, echipamente tehnologice si functionale care nu necesita montaj si echipamente de transport / Cost of Machinery & equipment that does not require assembly, and transport machinery
B32: 1
B33: 2
B34: TOTAL Utilaje, echipamente tehnologice si functionale care nu necesita montaj si echipamente de transport | D34: TOTAL Cost of Machinery & equipment that does not require assembly, and transport machinery | H34: =H32+H33 -> 0
B35: Dotari / Furniture, Fixtures
B36: 1
B37: 2
B38: TOTAL Dotari | D38: TOTAL Furniture, Fixtures | H38: =H36+H37 -> 0
B39: Active necorporale / Intangible assets
B40: 1
B41: 2
...

Sheet F5-08
B1: Nume Proiect / Project Title:Proiectare Si Executie Lucrari Pentru Obiectivul De Investitii: Sediu Nou Pentru Spitalul De Urgenta Prof. Dr. Dimitrie Gerota
B2: Numar Proiect / Project Number: 2S/2024
B3: Data / Date: Septembrie 2025
B4: Beneficiar / Beneficiary: Spitalul de Urgență ”Prof. Dr. Dimitrie Gerota”
B5: Proiectant General / General Designer: Asocierea CCN ALTYAPI YATIRIMLARI VE INSAAT A.S. - CCN YATIRIM HOLDING A.S.
B7: Formular F5: Fisele tehnice pentru echipamente, dotari | D7: F5 Form: Technical sheet for equipments, furniture and fixtures
B9: Nr. | C9: Specificatii tehnice impuse prin caietul de sarcini | D9: Technical specifications imposed by specification conditions - techincal notes | E9: Corespondenta propunerii tehnice cu specificatiile tehnice impuse prin caietul de sarcini / Correspondence of the technical proposal with the technical specifications imposed by the specification conditions | F9: Furnizor/Producator Provider/Manufacturer
B10: 0 | C10: 1 | D10: 1 | E10: 2 | F10: 3
B11: Fisa tehnica nr. 08 Utilajul, echipamentul tehnologic: Statie clorinare si tratare UV pentru rezerva hidranti - Cod schema F16 | D11: Technical sheet no. 08 Machinery, equipment: Chlorination and UV Water Treatment Plant for hydrants water tank - Scheme code F16
B12: 1 | C12: Parametrii tehnici si functionali Statie de clorinare digitala, recirculare apa si tratare UV inclusiv pompa de dozare, pentru rezervorul de stingere incendiu hidranti Alimentare: 100 – 240V AC – 50/60Hz Putere consumată: 100W Presiune: 2 – 12 bar Debit: min. 15 mc/h Racord contor apă: 3/4 țol Capacitate rezervor clor: 120 litri Rezervorul va avea agrement de potabilitate | D12: Technical and Functional Parameters Digital chlorination, water recirculation and UV treatment station, including dosing pump, for the fire-fighting water tank Power supply: 100 – 240 V AC, 50/60 Hz Power consumption: 100 W Pressure: 2 – 12 bar Flow rate: min. 15 m³/h Water meter connection: 3/4 inch Chlorine tank capacity: 120 liters Note: the tank will have potable water approval
B13: 2 | C13: Specificatii de performanta si conditii privind siguranta in exploatare Echipamentele vor fi insotite de cartea tehnica, certificat de calitate si garantie | D13: Performance specifications and operational safety conditions The equipment will be accompanied by the technical manual, certificate of quality, and warranty
B14: 3 | C14: Conditii privind conformitatea cu standardele relevante Echipamentul va fi fabricat cf. normelor UE ISO 9001, ISO 14001. | D14: Conditions regarding compliance with relevant standards The equipment shall be built in accordance with EU norms, ISO 9001, ISO 14001.
B15: 4 | C15: Conditii de garantie si postgarantie Garantie: minim 2 ani de la punerea in functiune, orice inlocuire a echipamentului in timpul perioadei de garantie va duce la preluarea garantiei de catre echipamentul nou instalat. | D15: Warranty and post-warranty conditions Warranty: minimum 2 years from the time of commissioning, any replacement of the equipment during the warranty period will lead to the warranty being taken over by the newly installed equipment.
B16: 5 | C16: Conditii cu caracter tehnic Furnizorul de echipament va oferi: Asistenta tehnica pentru instalare si punere in functiune. Manual de instructiuni pentru instalare si operare. Certificat de calitate. Training gratuit pentru personalul facilitatii. Service gratuit pe perioada garantiei in atelierele autorizate de intretinere si service. | D16: Technical conditions The equipment supplier will provide: - Technical assistance for installation and commissioning. - Installation and operating instructions manual. - Quality certificate. - Free training for the facility staff. - Free service during warranty in authorized maintenance and service workshops.

Sheet F5-09
B1: Nume Proiect / Project Title:Proiectare Si Executie Lucrari Pentru Obiectivul De Investitii: Sediu Nou Pentru Spitalul De Urgenta Prof. Dr. Dimitrie Gerota
B2: Numar Proiect / Project Number: 2S/2024
B3: Data / Date: Septembrie 2025
B4: Beneficiar / Beneficiary: Spitalul de Urgență ”Prof. Dr. Dimitrie Gerota”
B5: Proiectant General / General Designer: Asocierea CCN ALTYAPI YATIRIMLARI VE INSAAT A.S. - CCN YATIRIM HOLDING A.S.
B7: Formular F5: Fisele tehnice pentru echipamente, dotari | D7: F5 Form: Technical sheet for equipments, furniture and fixtures
B9: Nr. | C9: Specificatii tehnice impuse prin caietul de sarcini | D9: Technical specifications imposed by specification conditions - techincal notes | E9: Corespondenta propunerii tehnice cu specificatiile tehnice impuse prin caietul de sarcini / Correspondence of the technical proposal with the technical specifications imposed by the specification conditions | F9: Furnizor/Producator Provider/Manufacturer
B10: 0 | C10: 1 | D10: 1 | E10: 2 | F10: 3
B11: Fisa tehnica nr. 09 Utilajul, echipamentul tehnologic: Statie clorinare si tratare UV pentru rezerva sprinklere - Cod schema F17 | D11: Technical sheet no. 09 Machinery, equipment: Chlorination and UV Water Treatment Plant for hydrants water tank - Scheme code F17
B12: 1 | C12: Parametrii tehnici si functionali Statie de clorinare digitala, recirculare apa si tratare UV inclusiv pompa de dozare, pentru rezervorul de stingere incendiu sprinklere Alimentare: 100 – 240V AC – 50/60Hz Putere consumată: 100W Presiune: 2 – 12 bar Debit: min. 21 mc/h Racord contor apă: 3/4 țol Capacitate rezervor clor: 120 litri Rezervorul va avea agrement de potabilitate | D12: Technical and Functional Parameters Digital chlorination, water recirculation and UV treatment station, including dosing pump, for the fire-fighting water tank Power supply: 100 – 240 V AC, 50/60 Hz Power consumption: 100 W Pressure: 2 – 12 bar Flow rate: min. 21 m³/h Water meter connection: 3/4 inch Chlorine tank capacity: 120 liters Note: the tank will have potable water approval
B13: 2 | C13: Specificatii de performanta si conditii privind siguranta in exploatare Echipamentele vor fi insotite de cartea tehnica, certificat de calitate si garantie | D13: Performance specifications and operational safety conditions The equipment will be accompanied by the technical manual, certificate of quality, and warranty
B14: 3 | C14: Conditii privind conformitatea cu standardele relevante Echipamentul va fi fabricat cf. normelor UE ISO 9001, ISO 14001. | D14: Conditions regarding compliance with relevant standards The equipment shall be built in accordance with EU norms, ISO 9001, ISO 14001.
B15: 4 | C15: Conditii de garantie si postgarantie Garantie: minim 2 ani de la punerea in functiune, orice inlocuire a echipamentului in timpul perioadei de garantie va duce la preluarea garantiei de catre echipamentul nou instalat. | D15: Warranty and post-warranty conditions Warranty: minimum 2 years from the time of commissioning, any replacement of the equipment during the warranty period will lead to the warranty being taken over by the newly installed equipment.
B16: 5 | C16: Conditii cu caracter tehnic Furnizorul de echipament va oferi: Asistenta tehnica pentru instalare si punere in functiune. Manual de instructiuni pentru instalare si operare. Certificat de calitate. Training gratuit pentru personalul facilitatii. Service gratuit pe perioada garantiei in atelierele autorizate de intretinere si service. | D16: Technical conditions The equipment supplier will provide: - Technical assistance for installation and commissioning. - Installation and operating instructions manual. - Quality certificate. - Free training for the facility staff. - Free service during warranty in authorized maintenance and service workshops.

Sheet F5-15
B1: ='F4'!B1 -> Nume Proiect / Project Title:Proiectare Si Executie Lucrari Pentru Obiectivul De Investitii: Sediu Nou Pentru Spitalul De Urgenta Prof. Dr. Dimitrie Gerota
B2: ='F4'!B2 -> Numar Proiect / Project Number: 2S/2024
B3: ='F4'!B3 -> Data / Date: Septembrie 2025
B4: ='F4'!B4 -> Beneficiar / Beneficiary: Spitalul de Urgență ”Prof. Dr. Dimitrie Gerota”
B5: ='F4'!B5 -> Proiectant General / General Designer: Asocierea CCN ALTYAPI YATIRIMLARI VE INSAAT A.S. - CCN YATIRIM HOLDING A.S.
B7: Formular F5: Fisele tehnice pentru echipamente, dotari | D7: F5 Form: Technical sheet for equipments, furniture and fixtures
B9: Nr. | C9: Specificatii tehnice impuse prin caietul de sarcini | D9: Technical specifications imposed by specification conditions - techincal notes | E9: Corespondenta propunerii tehnice cu specificatiile tehnice impuse prin caietul de sarcini / Correspondence of the technical proposal with the technical specifications imposed by the specification conditions | F9: Furnizor/Producator Provider/Manufacturer
B10: 0 | C10: 1 | D10: 1 | E10: 2 | F10: 3
B11: Fisa tehnica nr. 15 Utilajul, echipamentul tehnologic: Statie dedurizare duplex pentru turnuri de racire - Cod schema W16 | D11: Technical sheet no. 15 Machinery, equipment: Duplex type water softening unit for domestic water - Scheme code W16
B12: 1 | C12: Parametrii tehnici si functionali Debit minim nominal: 50 mc/h. o Funcționare alternativă a rezervoarelor de rășină tip duplex o Regenerare controlată în funcție de volum o Supape sferice cu motor electric controlate prin PLC cu senzori de poziție finală o Doua coloane care vor functiona alternativ. - Poziționare flexibilă a rezervoarelor, a băii de sare și a suportului, după cum este necesar - Regenerare cu pat împachetat în contracurent pentru o capacitate sporită o Afișare și control al parametrilor sistemului o Ecran tactil și afișaj grafic o Structură standardizată a meniului o Opțional- conexiune Ethernet IP/TCP: Monitorizare la distanță - Afișare și control o Alarmă - Dozare precisă a saramurii datorită monitorizării conductivității - fără supradozare (consum de sare cu 60% mai mic în comparație cu dedurizatoarele tradiționale) - Design rezistent la coroziune - Presiune maxima: Pn16. | D12: Technical and functional parameters Nominal flow rate: 50 cbm/h. o Alternate operation of duplex resin tanks o Volume-controlled regeneration o PLC controlled electric motor ball valves with end position sensors o Two columns which will operate alternately. - Flexible positioning of tanks, salt bath and skid as required - Packed bed countercurrent regenerated for increased capacity o Display and control of the system parameters o Touchscreen and graphics display o Standardized menu structure o Optional– IP/TCP Ethernet connection: Remote monitoring - Display and control o Alarm - Precision brine dosing thanks to conductivity monitoring – no overdosing (60% less salt consumption in comparison to traditional softeners) - Corrosion resistant design - Presiune maxima: Pn16.
B13: 2 | C13: Specificatii de performanta si conditii privind siguranta in exploatare Echipamentele vor fi insotite de cartea tehnica, certificat de calitate si garantie | D13: Performance specifications and operational safety conditions The equipment will be accompanied by the technical manual, certificate of quality, and warranty
B14: 3 | C14: Conditii privind conformitatea cu standardele relevante Echipamentul va fi fabricat cf. normelor UE ISO 9001, ISO 14001. | D14: Conditions regarding compliance with relevant standards The equipment shall be built in accordance with EU norms, ISO 9001, ISO 14001.
B15: 4 | C15: Conditii de garantie si postgarantie Garantie: minim 2 ani de la punerea in functiune, orice inlocuire a echipamentului in timpul perioadei de garantie va duce la preluarea garantiei de catre echipamentul nou instalat. | D15: Warranty and post-warranty conditions Warranty: minimum 2 years from the time of commissioning, any replacement of the equipment during the warranty period will lead to the warranty being taken over by the newly installed equipment.
B16: 5 | C16: Conditii cu caracter tehnic Furnizorul de echipament va oferi: Asistenta tehnica pentru instalare si punere in functiune. Manual de instructiuni pentru instalare si operare. Certificat de calitate. Training gratuit pentru personalul facilitatii. Service gratuit pe perioada garantiei in atelierele autorizate de intretinere si service. | D16: Technical conditions The equipment supplier will provide: - Technical assistance for installation and commissioning. - Installation and operating instructions manual. - Quality certificate. - Free training for the facility staff. - Free service during warranty in authorized maintenance and service workshops.

Sheet F5-16
B1: ='F4'!B1 -> Nume Proiect / Project Title:Proiectare Si Executie Lucrari Pentru Obiectivul De Investitii: Sediu Nou Pentru Spitalul De Urgenta Prof. Dr. Dimitrie Gerota
B2: ='F4'!B2 -> Numar Proiect / Project Number: 2S/2024
B3: ='F4'!B3 -> Data / Date: Septembrie 2025
B4: ='F4'!B4 -> Beneficiar / Beneficiary: Spitalul de Urgență ”Prof. Dr. Dimitrie Gerota”
B5: ='F4'!B5 -> Proiectant General / General Designer: Asocierea CCN ALTYAPI YATIRIMLARI VE INSAAT A.S. - CCN YATIRIM HOLDING A.S.
B7: Formular F5: Fisele tehnice pentru echipamente, dotari | D7: F5 Form: Technical sheet for equipments, furniture and fixtures
B9: Nr. | C9: Specificatii tehnice impuse prin caietul de sarcini | D9: Technical specifications imposed by specification conditions - techincal notes | E9: Corespondenta propunerii tehnice cu specificatiile tehnice impuse prin caietul de sarcini / Correspondence of the technical proposal with the technical specifications imposed by the specification conditions | F9: Furnizor/Producator Provider/Manufacturer
B10: 0 | C10: 1 | D10: 1 | E10: 2 | F10: 3
B11: Fisa tehnica nr. 16 Utilajul, echipamentul tehnologic: Statie dedurizare duplex pentru apa dedurizata - Cod schema W12 | D11: Technical sheet no. 16 Machinery, equipment: Duplex type water softening unit for softened water tank - Scheme code W12
B12: 1 | C12: Parametrii tehnici si functionali Debit minim nominal: 15 mc/h. o Funcționare alternativă a rezervoarelor de rășină tip duplex o Regenerare controlată în funcție de volum o Supape sferice cu motor electric controlate prin PLC cu senzori de poziție finală o Doua coloane care vor functiona alternativ. - Poziționare flexibilă a rezervoarelor, a băii de sare și a suportului, după cum este necesar - Regenerare cu pat împachetat în contracurent pentru o capacitate sporită o Afișare și control al parametrilor sistemului o Ecran tactil și afișaj grafic o Structură standardizată a meniului o Opțional- conexiune Ethernet IP/TCP: Monitorizare la distanță - Afișare și control o Alarmă - Dozare precisă a saramurii datorită monitorizării conductivității - fără supradozare (consum de sare cu 60% mai mic în comparație cu dedurizatoarele tradiționale) - Design rezistent la coroziune - Presiune maxima: Pn16. | D12: Technical and functional parameters Nominal flow rate: 15 cbm/h. o Alternate operation of duplex resin tanks o Volume-controlled regeneration o PLC controlled electric motor ball valves with end position sensors o Two columns which will operate alternately. - Flexible positioning of tanks, salt bath and skid as required - Packed bed countercurrent regenerated for increased capacity o Display and control of the system parameters o Touchscreen and graphics display o Standardized menu structure o Optional– IP/TCP Ethernet connection: Remote monitoring - Display and control o Alarm - Precision brine dosing thanks to conductivity monitoring – no overdosing (60% less salt consumption in comparison to traditional softeners) - Corrosion resistant design - Presiune maxima: Pn16.
B13: 2 | C13: Specificatii de performanta si conditii privind siguranta in exploatare Echipamentele vor fi insotite de cartea tehnica, certificat de calitate si garantie | D13: Performance specifications and operational safety conditions The equipment will be accompanied by the technical manual, certificate of quality, and warranty
B14: 3 | C14: Conditii privind conformitatea cu standardele relevante Echipamentul va fi fabricat cf. normelor UE ISO 9001, ISO 14001. | D14: Conditions regarding compliance with relevant standards The equipment shall be built in accordance with EU norms, ISO 9001, ISO 14001.
B15: 4 | C15: Conditii de garantie si postgarantie Garantie: minim 2 ani de la punerea in functiune, orice inlocuire a echipamentului in timpul perioadei de garantie va duce la preluarea garantiei de catre echipamentul nou instalat. | D15: Warranty and post-warranty conditions Warranty: minimum 2 years from the time of commissioning, any replacement of the equipment during the warranty period will lead to the warranty being taken over by the newly installed equipment.
B16: 5 | C16: Conditii cu caracter tehnic Furnizorul de echipament va oferi: Asistenta tehnica pentru instalare si punere in functiune. Manual de instructiuni pentru instalare si operare. Certificat de calitate. Training gratuit pentru personalul facilitatii. Service gratuit pe perioada garantiei in atelierele autorizate de intretinere si service. | D16: Technical conditions The equipment supplier will provide: - Technical assistance for installation and commissioning. - Installation and operating instructions manual. - Quality certificate. - Free training for the facility staff. - Free service during warranty in authorized maintenance and service workshops.

Sheet F5-34
B1: ='F4'!B1 -> Nume Proiect / Project Title:Proiectare Si Executie Lucrari Pentru Obiectivul De Investitii: Sediu Nou Pentru Spitalul De Urgenta Prof. Dr. Dimitrie Gerota
B2: ='F4'!B2 -> Numar Proiect / Project Number: 2S/2024
B3: ='F4'!B3 -> Data / Date: Septembrie 2025
B4: ='F4'!B4 -> Beneficiar / Beneficiary: Spitalul de Urgență ”Prof. Dr. Dimitrie Gerota”
B5: ='F4'!B5 -> Proiectant General / General Designer: Asocierea CCN ALTYAPI YATIRIMLARI VE INSAAT A.S. - CCN YATIRIM HOLDING A.S.
B7: Formular F5: Fisele tehnice pentru echipamente, dotari | D7: F5 Form: Technical sheet for equipments, furniture and fixtures
B9: Nr. | C9: Specificatii tehnice impuse prin caietul de sarcini | D9: Technical specifications imposed by specification conditions - techincal notes | E9: Corespondenta propunerii tehnice cu specificatiile tehnice impuse prin caietul de sarcini / Correspondence of the technical proposal with the technical specifications imposed by the specification conditions | F9: Furnizor/Producator Provider/Manufacturer
B10: 0 | C10: 1 | D10: 1 | E10: 2 | F10: 3
B11: Fisa tehnica nr. 34 Utilajul, echipamentul tehnologic: Sterilizator UV apa rece potabila | D11: Technical sheet no. 34 Machinery, equipment: UV sterilizer for potable cold water
B12: 1 | C12: Parametrii tehnici si functionali - dezinfectare cu lampa cu ultraviolete - sistem cu posibilitate de curatare manual/automat - contoller local cu monitorizare continua a temperaturii, stari de alarma, eroare, ajustare parametri | D12: Technical and functional parameters - disinfection with ultraviolete lamp - system with possibility of manual/automatic wipin - local contoller with continuous monitoring of temperature, faults, errors, parameter adjustment
B13: 2 | C13: Specificatii de performanta si conditii privind siguranta in exploatare Echipamentele vor fi insotite de cartea tehnica, certificat de calitate si garantie | D13: Performance specifications and operational safety conditions The equipment will be accompanied by the technical manual, certificate of quality, and warranty
B14: 3 | C14: Conditii privind conformitatea cu standardele relevante Echipamentul va fi fabricat cf. normelor UE ISO 9001, ISO 14001. | D14: Conditions regarding compliance with relevant standards The equipment shall be built in accordance with EU norms, ISO 9001, ISO 14001.
B15: 4 | C15: Conditii de garantie si postgarantie Garantie: minim 2 ani de la punerea in functiune, orice inlocuire a echipamentului in timpul perioadei de garantie va duce la preluarea garantiei de catre echipamentul nou instalat. | D15: Warranty and post-warranty conditions Warranty: minimum 2 years from the time of commissioning, any replacement of the equipment during the warranty period will lead to the warranty being taken over by the newly installed equipment.
B16: 5 | C16: Conditii cu caracter tehnic Furnizorul de echipament va oferi: Asistenta tehnica pentru instalare si punere in functiune. Manual de instructiuni pentru instalare si operare. Certificat de calitate. Training gratuit pentru personalul facilitatii. Service gratuit pe perioada garantiei in atelierele autorizate de intretinere si service. | D16: Technical conditions The equipment supplier will provide: - Technical assistance for installation and commissioning. - Installation and operating instructions manual. - Quality certificate. - Free training for the facility staff. - Free service during warranty in authorized maintenance and service workshops.

Sheet F5-35
B1: ='F4'!B1 -> Nume Proiect / Project Title:Proiectare Si Executie Lucrari Pentru Obiectivul De Investitii: Sediu Nou Pentru Spitalul De Urgenta Prof. Dr. Dimitrie Gerota
B2: ='F4'!B2 -> Numar Proiect / Project Number: 2S/2024
B3: ='F4'!B3 -> Data / Date: Septembrie 2025
B4: ='F4'!B4 -> Beneficiar / Beneficiary: Spitalul de Urgență ”Prof. Dr. Dimitrie Gerota”
B5: ='F4'!B5 -> Proiectant General / General Designer: Asocierea CCN ALTYAPI YATIRIMLARI VE INSAAT A.S. - CCN YATIRIM HOLDING A.S.
B7: Formular F5: Fisele tehnice pentru echipamente, dotari | D7: F5 Form: Technical sheet for equipments, furniture and fixtures
B9: Nr. | C9: Specificatii tehnice impuse prin caietul de sarcini | D9: Technical specifications imposed by specification conditions - techincal notes | E9: Corespondenta propunerii tehnice cu specificatiile tehnice impuse prin caietul de sarcini / Correspondence of the technical proposal with the technical specifications imposed by the specification conditions | F9: Furnizor/Producator Provider/Manufacturer
B10: 0 | C10: 1 | D10: 1 | E10: 2 | F10: 3
B11: Fisa tehnica nr. 35 Utilajul, echipamentul tehnologic:Filtru cu carbon activ tip duplex - Cod schema W25 | D11: Technical sheet no. 35 Machinery, equipment: Duplex type activated carbon filter - Scheme code W25
B12: 1 | C12: Parametrii tehnici si functionali Debit minim nominal: 18 mc/h. Produs din material rezistent la coroziune cu durabilitate ridicată - Alimentare neîntreruptă cu apă proaspătă datorită filtrării duplex - Funcționare complet automată - supape electrice și transmițătoare de presiune - Spălare inversă automată - PLC de calitate industrială și panou tactil o Afișare și control al parametrilor sistemului o Ecran tactil și afișaj grafic o Structură standardizată a meniului o Conexiune Ethernet opțională: Monitorizare la distanță - Afișare și control o Alarmă - IP/TCP - Fabricat în UE - Alimentare neîntreruptă cu apă proaspătă datorită filtrării duplex - Funcționare complet automată - Spălare inversă automată Toata statie se va furniza complet de catre un producator de specialitate Echipamentele statiei de tratare vor fi stabilite in functie de parametrii din buletinul de analiza. | D12: Technical and functional parameters Nominal flow rate: 18 cbm/h. Produced in corrosion resistant material with high durability - Uninterrupted Fresh Water supply thanks to Duplex Filtration - Fully automatic operation - Electrical valves and pressure transmitters - automatic backwash - Industrial grade PLC and touch panel o Display and control of the system parameters o Touchscreen and graphics Display o Standardized menu structure o Optional Ethernet connection: Remote monitoring - Display and control o Alarm – IP/TCP - Manufactured within the EU - Uninterrupted supply of fresh water thanks to duplex filtration - Fully automatic operation - Automatic backwash The whole station will be completely supplied by a specialized manufacturer The equipment of the treatment station will be established according to the parameters in the analysis bulletin.
B13: 2 | C13: Specificatii de performanta si conditii privind siguranta in exploatare Echipamentele vor fi insotite de cartea tehnica, certificat de calitate si garantie | D13: Performance specifications and operational safety conditions The equipment will be accompanied by the technical manual, certificate of quality, and warranty
B14: 3 | C14: Conditii privind conformitatea cu standardele relevante Echipamentul va fi fabricat cf. normelor UE ISO 9001, ISO 14001. | D14: Conditions regarding compliance with relevant standards The equipment shall be built in accordance with EU norms, ISO 9001, ISO 14001.
B15: 4 | C15: Conditii de garantie si postgarantie Garantie: minim 2 ani de la punerea in functiune, orice inlocuire a echipamentului in timpul perioadei de garantie va duce la preluarea garantiei de catre echipamentul nou instalat. | D15: Warranty and post-warranty conditions Warranty: minimum 2 years from the time of commissioning, any replacement of the equipment during the warranty period will lead to the warranty being taken over by the newly installed equipment.
B16: 5 | C16: Conditii cu caracter tehnic Furnizorul de echipament va oferi: Asistenta tehnica pentru instalare si punere in functiune. Manual de instructiuni pentru instalare si operare. Certificat de calitate. Training gratuit pentru personalul facilitatii. Service gratuit pe perioada garantiei in atelierele autorizate de intretinere si service. | D16: Technical conditions The equipment supplier will provide: - Technical assistance for installation and commissioning. - Installation and operating instructions manual. - Quality certificate. - Free training for the facility staff. - Free service during warranty in authorized maintenance and service workshops.

Sheet F5-36
B1: ='F4'!B1 -> Nume Proiect / Project Title:Proiectare Si Executie Lucrari Pentru Obiectivul De Investitii: Sediu Nou Pentru Spitalul De Urgenta Prof. Dr. Dimitrie Gerota
B2: ='F4'!B2 -> Numar Proiect / Project Number: 2S/2024
B3: ='F4'!B3 -> Data / Date: Septembrie 2025
B4: ='F4'!B4 -> Beneficiar / Beneficiary: Spitalul de Urgență ”Prof. Dr. Dimitrie Gerota”
B5: ='F4'!B5 -> Proiectant General / General Designer: Asocierea CCN ALTYAPI YATIRIMLARI VE INSAAT A.S. - CCN YATIRIM HOLDING A.S.
B7: Formular F5: Fisele tehnice pentru echipamente, dotari | D7: F5 Form: Technical sheet for equipments, furniture and fixtures
B9: Nr. | C9: Specificatii tehnice impuse prin caietul de sarcini | D9: Technical specifications imposed by specification conditions - techincal notes | E9: Corespondenta propunerii tehnice cu specificatiile tehnice impuse prin caietul de sarcini / Correspondence of the technical proposal with the technical specifications imposed by the specification conditions | F9: Furnizor/Producator Provider/Manufacturer
B10: 0 | C10: 1 | D10: 1 | E10: 2 | F10: 3
B11: Fisa tehnica nr. 36 Utilajul, echipamentul tehnologic: Statie osmoza inversa - Cod schema W24 | D11: Technical sheet no. 36 Machinery, equipment: Reverse osmosis unit - Scheme code W24
B12: 1 | C12: Parametrii tehnici si functionali Debit minim nominal: 18 mc/h. - Instalare pe un cadru din oțel inoxidabil cu acces facil la toate componentele - Clătire automată la interval timp și calitate, pentru a asigura permeabilitatea și pentru a proteja membranele - Inclusiv sistem curățare eficientă a membranelor - Pompă de dozare anticalcar montată pe un suport - Pompă de rapel controlată în funcție de frecvență - asigură o funcționare fiabilă în zone cu presiuni și temperaturi fluctuante ale apei o Nivel ridicat de eficiență energetică și nivel redus de zgomot o Membrane de joasă presiune pentru economie de energie o Retenție de sare de până la 99,3 %. o Tuburi de presiune pentru schimbarea rapidă a membranelor Toata statie se va furniza complet de catre un producator de specialitate Echipamentele statiei de tratare vor fi stabilite in functie de parametrii din buletinul de analiza. | D12: Technical and functional parameters Nominal flow rate: 18 cbm/h. - Installation on a stainless steel frame with optimum access to all components - Automated time and quality rinsing, to ensure permeability and to protect the membranes - Including effective cleaning of the membranes - Anti Scaling dosing pump skid mounted - Frequency-controled booster pump - ensures reliable operation in areas with fluctuating water pressures and temperatures o High energy efficiency level and low noice level o Energy-saving low-pressure membranes o Salt retention up to 99.3% o Pressure tubes for fast membrane changes The whole station will be completely supplied by a specialized manufacturer The equipment of the treatment station will be established according to the parameters in the analysis bulletin.
B13: 2 | C13: Specificatii de performanta si conditii privind siguranta in exploatare Echipamentele vor fi insotite de cartea tehnica, certificat de calitate si garantie | D13: Performance specifications and operational safety conditions The equipment will be accompanied by the technical manual, certificate of quality, and warranty
B14: 3 | C14: Conditii privind conformitatea cu standardele relevante Echipamentul va fi fabricat cf. normelor UE ISO 9001, ISO 14001. | D14: Conditions regarding compliance with relevant standards The equipment shall be built in accordance with EU norms, ISO 9001, ISO 14001.
B15: 4 | C15: Conditii de garantie si postgarantie Garantie: minim 2 ani de la punerea in functiune, orice inlocuire a echipamentului in timpul perioadei de garantie va duce la preluarea garantiei de catre echipamentul nou instalat. | D15: Warranty and post-warranty conditions Warranty: minimum 2 years from the time of commissioning, any replacement of the equipment during the warranty period will lead to the warranty being taken over by the newly installed equipment.
B16: 5 | C16: Conditii cu caracter tehnic Furnizorul de echipament va oferi: Asistenta tehnica pentru instalare si punere in functiune. Manual de instructiuni pentru instalare si operare. Certificat de calitate. Training gratuit pentru personalul facilitatii. Service gratuit pe perioada garantiei in atelierele autorizate de intretinere si service. | D16: Technical conditions The equipment supplier will provide: - Technical assistance for installation and commissioning. - Installation and operating instructions manual. - Quality certificate. - Free training for the facility staff. - Free service during warranty in authorized maintenance and service workshops.

Sheet F5-37
B1: ='F4'!B1 -> Nume Proiect / Project Title:Proiectare Si Executie Lucrari Pentru Obiectivul De Investitii: Sediu Nou Pentru Spitalul De Urgenta Prof. Dr. Dimitrie Gerota
B2: ='F4'!B2 -> Numar Proiect / Project Number: 2S/2024
B3: ='F4'!B3 -> Data / Date: Septembrie 2025
B4: ='F4'!B4 -> Beneficiar / Beneficiary: Spitalul de Urgență ”Prof. Dr. Dimitrie Gerota”
B5: ='F4'!B5 -> Proiectant General / General Designer: Asocierea CCN ALTYAPI YATIRIMLARI VE INSAAT A.S. - CCN YATIRIM HOLDING A.S.
B7: Formular F5: Fisele tehnice pentru echipamente, dotari | D7: F5 Form: Technical sheet for equipments, furniture and fixtures
B9: Nr. | C9: Specificatii tehnice impuse prin caietul de sarcini | D9: Technical specifications imposed by specification conditions - techincal notes | E9: Corespondenta propunerii tehnice cu specificatiile tehnice impuse prin caietul de sarcini / Correspondence of the technical proposal with the technical specifications imposed by the specification conditions | F9: Furnizor/Producator Provider/Manufacturer
B10: 0 | C10: 1 | D10: 1 | E10: 2 | F10: 3
B11: Fisa tehnica nr. 37 Utilajul, echipamentul tehnologic: Sistem dozare substante dezinfectante pentru apa potabila | D11: Technical sheet no. 37 Machinery, equipment: Dosing system for disinfectant substances for potable water
B12: 1 | C12: Parametrii tehnici si functionali - Max. 40 l/h și 16 bar - Raport de reducere între 1:3000 și 1:1000 - FlowControl cu diagnosticare selectivă a defecțiunilor - Măsurare integrată a debitului - funcție care permite ajustarea vitezei pompei la cerinţele aplicaţiei - Dezaerare automată chiar și în timpul perioadei de repaus a pompei - Moduri de funcționare pe intervale (pe bază de cronometru sau de impulsuri) - ProfiBus opțional - Motor în trepte, puternic, cu viteză variabilă - Control intern al vitezei cursei - Cursă completă în permanență - chiar și la debite mici - Dozare lină și continuă - Optim pentru degazarea lichidelor - Funcție pentru lichide cu vâscozitate ridicată | D12: Technical and functional parameters - Max. 40 l/h and 16 bar - Turn-down ratio 1:3000 or 1:1000 - FlowControl with selective fault diagnosis - Integrated flow measurement - function that allows adjusting the pump speed to the requirements of the application - Auto deaeration also during pump standby - Batch modes (timer- or pulse-based) - Optional Profibus - Powerful variable-speed stepper motor - Internal stroke speed control - Always full stroke length – even at small flow rates - Smooth, continuous dosing - Optimal for degassing liquids - Function for high-viscosity liquids
B13: 2 | C13: Specificatii de performanta si conditii privind siguranta in exploatare Echipamentele vor fi insotite de cartea tehnica, certificat de calitate si garantie | D13: Performance specifications and operational safety conditions The equipment will be accompanied by the technical manual, certificate of quality, and warranty
B14: 3 | C14: Conditii privind conformitatea cu standardele relevante Echipamentul va fi fabricat cf. normelor UE ISO 9001, ISO 14001. | D14: Conditions regarding compliance with relevant standards The equipment shall be built in accordance with EU norms, ISO 9001, ISO 14001.
B15: 4 | C15: Conditii de garantie si postgarantie Garantie: minim 2 ani de la punerea in functiune, orice inlocuire a echipamentului in timpul perioadei de garantie va duce la preluarea garantiei de catre echipamentul nou instalat. | D15: Warranty and post-warranty conditions Warranty: minimum 2 years from the time of commissioning, any replacement of the equipment during the warranty period will lead to the warranty being taken over by the newly installed equipment.
B16: 5 | C16: Conditii cu caracter tehnic Furnizorul de echipament va oferi: Asistenta tehnica pentru instalare si punere in functiune. Manual de instructiuni pentru instalare si operare. Certificat de calitate. Training gratuit pentru personalul facilitatii. Service gratuit pe perioada garantiei in atelierele autorizate de intretinere si service. | D16: Technical conditions The equipment supplier will provide: - Technical assistance for installation and commissioning. - Installation and operating instructions manual. - Quality certificate. - Free training for the facility staff. - Free service during warranty in authorized maintenance and service workshops.

Sheet F5-38
B1: ='F4'!B1 -> Nume Proiect / Project Title:Proiectare Si Executie Lucrari Pentru Obiectivul De Investitii: Sediu Nou Pentru Spitalul De Urgenta Prof. Dr. Dimitrie Gerota
B2: ='F4'!B2 -> Numar Proiect / Project Number: 2S/2024
B3: ='F4'!B3 -> Data / Date: Septembrie 2025
B4: ='F4'!B4 -> Beneficiar / Beneficiary: Spitalul de Urgență ”Prof. Dr. Dimitrie Gerota”
B5: ='F4'!B5 -> Proiectant General / General Designer: Asocierea CCN ALTYAPI YATIRIMLARI VE INSAAT A.S. - CCN YATIRIM HOLDING A.S.
B7: Formular F5: Fisele tehnice pentru echipamente, dotari | D7: F5 Form: Technical sheet for equipments, furniture and fixtures
B9: Nr. | C9: Specificatii tehnice impuse prin caietul de sarcini | D9: Technical specifications imposed by specification conditions - techincal notes | E9: Corespondenta propunerii tehnice cu specificatiile tehnice impuse prin caietul de sarcini / Correspondence of the technical proposal with the technical specifications imposed by the specification conditions | F9: Furnizor/Producator Provider/Manufacturer
B10: 0 | C10: 1 | D10: 1 | E10: 2 | F10: 3
B11: Fisa tehnica nr. 38 Utilajul, echipamentul tehnologic: Sistem dozare substante floculante pentru apa de adaos instalatii HVAC | D11: Technical sheet no. 38 Machinery, equipment: Dosing system for flocculant substances for HVAC systems makeup water
B12: 1 | C12: Parametrii tehnici si functionali - Max. 40 l/h și 16 bar - Raport de reducere între 1:3000 și 1:1000 - FlowControl cu diagnosticare selectivă a defecțiunilor - Măsurare integrată a debitului - funcție care permite ajustarea vitezei pompei la cerinţele aplicaţiei - Dezaerare automată chiar și în timpul perioadei de repaus a pompei - Moduri de funcționare pe intervale (pe bază de cronometru sau de impulsuri) - ProfiBus opțional - Motor în trepte, puternic, cu viteză variabilă - Control intern al vitezei cursei - Cursă completă în permanență - chiar și la debite mici - Dozare lină și continuă - Optim pentru degazarea lichidelor - Funcție pentru lichide cu vâscozitate ridicată | D12: Technical and functional parameters - Max. 40 l/h and 16 bar - Turn-down ratio 1:3000 (7.5-16) or 1:1000 - FlowControl with selective fault diagnosis - Integrated flow measurement - function that allows adjusting the pump speed to the requirements of the application - Auto deaeration also during pump standby - Batch modes (timer- or pulse-based) - Optional Profibus - Powerful variable-speed stepper motor - Internal stroke speed control - Always full stroke length – even at small flow rates - Smooth, continuous dosing - Optimal for degassing liquids - function for high-viscosity liquids
B13: 2 | C13: Specificatii de performanta si conditii privind siguranta in exploatare Echipamentele vor fi insotite de cartea tehnica, certificat de calitate si garantie | D13: Performance specifications and operational safety conditions The equipment will be accompanied by the technical manual, certificate of quality, and warranty
B14: 3 | C14: Conditii privind conformitatea cu standardele relevante Echipamentul va fi fabricat cf. normelor UE ISO 9001, ISO 14001. | D14: Conditions regarding compliance with relevant standards The equipment shall be built in accordance with EU norms, ISO 9001, ISO 14001.
B15: 4 | C15: Conditii de garantie si postgarantie Garantie: minim 2 ani de la punerea in functiune, orice inlocuire a echipamentului in timpul perioadei de garantie va duce la preluarea garantiei de catre echipamentul nou instalat. | D15: Warranty and post-warranty conditions Warranty: minimum 2 years from the time of commissioning, any replacement of the equipment during the warranty period will lead to the warranty being taken over by the newly installed equipment.
B16: 5 | C16: Conditii cu caracter tehnic Furnizorul de echipament va oferi: Asistenta tehnica pentru instalare si punere in functiune. Manual de instructiuni pentru instalare si operare. Certificat de calitate. Training gratuit pentru personalul facilitatii. Service gratuit pe perioada garantiei in atelierele autorizate de intretinere si service. | D16: Technical conditions The equipment supplier will provide: - Technical assistance for installation and commissioning. - Installation and operating instructions manual. - Quality certificate. - Free training for the facility staff. - Free service during warranty in authorized maintenance and service workshops.

Sheet F5-39
B1: ='F4'!B1 -> Nume Proiect / Project Title:Proiectare Si Executie Lucrari Pentru Obiectivul De Investitii: Sediu Nou Pentru Spitalul De Urgenta Prof. Dr. Dimitrie Gerota
B2: ='F4'!B2 -> Numar Proiect / Project Number: 2S/2024
B3: ='F4'!B3 -> Data / Date: Septembrie 2025
B4: ='F4'!B4 -> Beneficiar / Beneficiary: Spitalul de Urgență ”Prof. Dr. Dimitrie Gerota”
B5: ='F4'!B5 -> Proiectant General / General Designer: Asocierea CCN ALTYAPI YATIRIMLARI VE INSAAT A.S. - CCN YATIRIM HOLDING A.S.
B7: Formular F5: Fisele tehnice pentru echipamente, dotari | D7: F5 Form: Technical sheet for equipments, furniture and fixtures
B9: Nr. | C9: Specificatii tehnice impuse prin caietul de sarcini | D9: Technical specifications imposed by specification conditions - techincal notes | E9: Corespondenta propunerii tehnice cu specificatiile tehnice impuse prin caietul de sarcini / Correspondence of the technical proposal with the technical specifications imposed by the specification conditions | F9: Furnizor/Producator Provider/Manufacturer
B10: 0 | C10: 1 | D10: 1 | E10: 2 | F10: 3
B11: Fisa tehnica nr. 39 Utilajul, echipamentul tehnologic: Sistem dozare substante anti-alge pentru apa de adaos turnuri de racire | D11: Technical sheet no. 39 Machinery, equipment: Dosing system for anti-algae substances for cooling towers makeup water
B12: 1 | C12: Parametrii tehnici si functionali - Max. 40 l/h și 16 bar - Raport de reducere între 1:3000 și 1:1000 - FlowControl cu diagnosticare selectivă a defecțiunilor - Măsurare integrată a debitului - funcție care permite ajustarea vitezei pompei la cerinţele aplicaţiei - Dezaerare automată chiar și în timpul perioadei de repaus a pompei - Moduri de funcționare pe intervale (pe bază de cronometru sau de impulsuri) - ProfiBus opțional - Motor în trepte, puternic, cu viteză variabilă - Control intern al vitezei cursei - Cursă completă în permanență - chiar și la debite mici - Dozare lină și continuă - Optim pentru degazarea lichidelor - Funcție pentru lichide cu vâscozitate ridicată | D12: Technical and functional parameters - Max. 40 l/h and 16 bar - Turn-down ratio 1:3000 (7.5-16) or 1:1000 - FlowControl with selective fault diagnosis - Integrated flow measurement - function that allows adjusting the pump speed to the requirements of the application - Auto deaeration also during pump standby - Batch modes (timer- or pulse-based) - Optional Profibus - Powerful variable-speed stepper motor - Internal stroke speed control - Always full stroke length – even at small flow rates - Smooth, continuous dosing - Optimal for degassing liquids - function for high-viscosity liquids
B13: 2 | C13: Specificatii de performanta si conditii privind siguranta in exploatare Echipamentele vor fi insotite de cartea tehnica, certificat de calitate si garantie | D13: Performance specifications and operational safety conditions The equipment will be accompanied by the technical manual, certificate of quality, and warranty
B14: 3 | C14: Conditii privind conformitatea cu standardele relevante Echipamentul va fi fabricat cf. normelor UE ISO 9001, ISO 14001. | D14: Conditions regarding compliance with relevant standards The equipment shall be built in accordance with EU norms, ISO 9001, ISO 14001.
B15: 4 | C15: Conditii de garantie si postgarantie Garantie: minim 2 ani de la punerea in functiune, orice inlocuire a echipamentului in timpul perioadei de garantie va duce la preluarea garantiei de catre echipamentul nou instalat. | D15: Warranty and post-warranty conditions Warranty: minimum 2 years from the time of commissioning, any replacement of the equipment during the warranty period will lead to the warranty being taken over by the newly installed equipment.
B16: 5 | C16: Conditii cu caracter tehnic Furnizorul de echipament va oferi: Asistenta tehnica pentru instalare si punere in functiune. Manual de instructiuni pentru instalare si operare. Certificat de calitate. Training gratuit pentru personalul facilitatii. Service gratuit pe perioada garantiei in atelierele autorizate de intretinere si service. | D16: Technical conditions The equipment supplier will provide: - Technical assistance for installation and commissioning. - Installation and operating instructions manual. - Quality certificate. - Free training for the facility staff. - Free service during warranty in authorized maintenance and service workshops.

Sheet F5-40
B1: ='F4'!B1 -> Nume Proiect / Project Title:Proiectare Si Executie Lucrari Pentru Obiectivul De Investitii: Sediu Nou Pentru Spitalul De Urgenta Prof. Dr. Dimitrie Gerota
B2: ='F4'!B2 -> Numar Proiect / Project Number: 2S/2024
B3: ='F4'!B3 -> Data / Date: Septembrie 2025
B4: ='F4'!B4 -> Beneficiar / Beneficiary: Spitalul de Urgență ”Prof. Dr. Dimitrie Gerota”
B5: ='F4'!B5 -> Proiectant General / General Designer: Asocierea CCN ALTYAPI YATIRIMLARI VE INSAAT A.S. - CCN YATIRIM HOLDING A.S.
B7: Formular F5: Fisele tehnice pentru echipamente, dotari | D7: F5 Form: Technical sheet for equipments, furniture and fixtures
B9: Nr. | C9: Specificatii tehnice impuse prin caietul de sarcini | D9: Technical specifications imposed by specification conditions - techincal notes | E9: Corespondenta propunerii tehnice cu specificatiile tehnice impuse prin caietul de sarcini / Correspondence of the technical proposal with the technical specifications imposed by the specification conditions | F9: Furnizor/Producator Provider/Manufacturer
B10: 0 | C10: 1 | D10: 1 | E10: 2 | F10: 3
B11: Fisa tehnica nr. 40 Utilajul, echipamentul tehnologic: Sistem dozare substante anti-coroziune si anti-depuneri pentru apa | D11: Technical sheet no. 40 Machinery, equipment: Dosing system for anti-corrosion and anti-scaling substances for water
B12: 1 | C12: Parametrii tehnici si functionali - Max. 40 l/h și 16 bar - Raport de reducere între 1:3000 și 1:1000 - FlowControl cu diagnosticare selectivă a defecțiunilor - Măsurare integrată a debitului - funcție care permite ajustarea vitezei pompei la cerinţele aplicaţiei - Dezaerare automată chiar și în timpul perioadei de repaus a pompei - Moduri de funcționare pe intervale (pe bază de cronometru sau de impulsuri) - ProfiBus opțional - Motor în trepte, puternic, cu viteză variabilă - Control intern al vitezei cursei - Cursă completă în permanență - chiar și la debite mici - Dozare lină și continuă - Optim pentru degazarea lichidelor - Funcție pentru lichide cu vâscozitate ridicată | D12: Technical and functional parameters - Max. 40 l/h and 16 bar - Turn-down ratio 1:3000 (7.5-16) or 1:1000 - FlowControl with selective fault diagnosis - Integrated flow measurement - function that allows adjusting the pump speed to the requirements of the application - Auto deaeration also during pump standby - Batch modes (timer- or pulse-based) - Optional Profibus - Powerful variable-speed stepper motor - Internal stroke speed control - Always full stroke length – even at small flow rates - Smooth, continuous dosing - Optimal for degassing liquids - function for high-viscosity liquids
B13: 2 | C13: Specificatii de performanta si conditii privind siguranta in exploatare Echipamentele vor fi insotite de cartea tehnica, certificat de calitate si garantie | D13: Performance specifications and operational safety conditions The equipment will be accompanied by the technical manual, certificate of quality, and warranty
B14: 3 | C14: Conditii privind conformitatea cu standardele relevante Echipamentul va fi fabricat cf. normelor UE ISO 9001, ISO 14001. | D14: Conditions regarding compliance with relevant standards The equipment shall be built in accordance with EU norms, ISO 9001, ISO 14001.
B15: 4 | C15: Conditii de garantie si postgarantie Garantie: minim 2 ani de la punerea in functiune, orice inlocuire a echipamentului in timpul perioadei de garantie va duce la preluarea garantiei de catre echipamentul nou instalat. | D15: Warranty and post-warranty conditions Warranty: minimum 2 years from the time of commissioning, any replacement of the equipment during the warranty period will lead to the warranty being taken over by the newly installed equipment.
B16: 5 | C16: Conditii cu caracter tehnic Furnizorul de echipament va oferi: Asistenta tehnica pentru instalare si punere in functiune. Manual de instructiuni pentru instalare si operare. Certificat de calitate. Training gratuit pentru personalul facilitatii. Service gratuit pe perioada garantiei in atelierele autorizate de intretinere si service. | D16: Technical conditions The equipment supplier will provide: - Technical assistance for installation and commissioning. - Installation and operating instructions manual. - Quality certificate. - Free training for the facility staff. - Free service during warranty in authorized maintenance and service workshops.

Sheet F5-41
B1: ='F4'!B1 -> Nume Proiect / Project Title:Proiectare Si Executie Lucrari Pentru Obiectivul De Investitii: Sediu Nou Pentru Spitalul De Urgenta Prof. Dr. Dimitrie Gerota
B2: ='F4'!B2 -> Numar Proiect / Project Number: 2S/2024
B3: ='F4'!B3 -> Data / Date: Septembrie 2025
B4: ='F4'!B4 -> Beneficiar / Beneficiary: Spitalul de Urgență ”Prof. Dr. Dimitrie Gerota”
B5: ='F4'!B5 -> Proiectant General / General Designer: Asocierea CCN ALTYAPI YATIRIMLARI VE INSAAT A.S. - CCN YATIRIM HOLDING A.S.
B7: Formular F5: Fisele tehnice pentru echipamente, dotari | D7: F5 Form: Technical sheet for equipments, furniture and fixtures
B9: Nr. | C9: Specificatii tehnice impuse prin caietul de sarcini | D9: Technical specifications imposed by specification conditions - techincal notes | E9: Corespondenta propunerii tehnice cu specificatiile tehnice impuse prin caietul de sarcini / Correspondence of the technical proposal with the technical specifications imposed by the specification conditions | F9: Furnizor/Producator Provider/Manufacturer
B10: 0 | C10: 1 | D10: 1 | E10: 2 | F10: 3
B11: Fisa tehnica nr. 41 Utilajul, echipamentul tehnologic: Unitate de dozare pentru monocloramina | D11: Technical sheet no. 41 Machinery, equipment: Dosing unit for monochloramine
B12: 1 | C12: Parametrii tehnici si functionali - Max. 40 l/h și 16 bar - Raport de reducere între 1:3000 și 1:1000 - FlowControl cu diagnosticare selectivă a defecțiunilor - Măsurare integrată a debitului - funcție care permite ajustarea vitezei pompei la cerinţele aplicaţiei - Dezaerare automată chiar și în timpul perioadei de repaus a pompei - Moduri de funcționare pe intervale (pe bază de cronometru sau de impulsuri) - ProfiBus opțional - Motor în trepte, puternic, cu viteză variabilă - Control intern al vitezei cursei - Cursă completă în permanență - chiar și la debite mici - Dozare lină și continuă - Optim pentru degazarea lichidelor - Funcție pentru lichide cu vâscozitate ridicată | D12: Technical and functional parameters - Max. 40 l/h and 16 bar - Turn-down ratio 1:3000 (7.5-16) or 1:1000 - FlowControl with selective fault diagnosis - Integrated flow measurement - function that allows adjusting the pump speed to the requirements of the application - Auto deaeration also during pump standby - Batch modes (timer- or pulse-based) - Optional Profibus - Powerful variable-speed stepper motor - Internal stroke speed control - Always full stroke length – even at small flow rates - Smooth, continuous dosing - Optimal for degassing liquids - Function for high-viscosity liquids
B13: 2 | C13: Specificatii de performanta si conditii privind siguranta in exploatare Echipamentele vor fi insotite de cartea tehnica, certificat de calitate si garantie | D13: Performance specifications and operational safety conditions The equipment will be accompanied by the technical manual, certificate of quality, and warranty
B14: 3 | C14: Conditii privind conformitatea cu standardele relevante Echipamentul va fi fabricat cf. normelor UE ISO 9001, ISO 14001. | D14: Conditions regarding compliance with relevant standards The equipment shall be built in accordance with EU norms, ISO 9001, ISO 14001.
B15: 4 | C15: Conditii de garantie si postgarantie Garantie: minim 2 ani de la punerea in functiune, orice inlocuire a echipamentului in timpul perioadei de garantie va duce la preluarea garantiei de catre echipamentul nou instalat. | D15: Warranty and post-warranty conditions Warranty: minimum 2 years from the time of commissioning, any replacement of the equipment during the warranty period will lead to the warranty being taken over by the newly installed equipment.
B16: 5 | C16: Conditii cu caracter tehnic Furnizorul de echipament va oferi: Asistenta tehnica pentru instalare si punere in functiune. Manual de instructiuni pentru instalare si operare. Certificat de calitate. Training gratuit pentru personalul facilitatii. Service gratuit pe perioada garantiei in atelierele autorizate de intretinere si service. | D16: Technical conditions The equipment supplier will provide: - Technical assistance for installation and commissioning. - Installation and operating instructions manual. - Quality certificate. - Free training for the facility staff. - Free service during warranty in authorized maintenance and service workshops.

Sheet F5-42
B1: ='F4'!B1 -> Nume Proiect / Project Title:Proiectare Si Executie Lucrari Pentru Obiectivul De Investitii: Sediu Nou Pentru Spitalul De Urgenta Prof. Dr. Dimitrie Gerota
B2: ='F4'!B2 -> Numar Proiect / Project Number: 2S/2024
B3: ='F4'!B3 -> Data / Date: Septembrie 2025
B4: ='F4'!B4 -> Beneficiar / Beneficiary: Spitalul de Urgență ”Prof. Dr. Dimitrie Gerota”
B5: ='F4'!B5 -> Proiectant General / General Designer: Asocierea CCN ALTYAPI YATIRIMLARI VE INSAAT A.S. - CCN YATIRIM HOLDING A.S.
B7: Formular F5: Fisele tehnice pentru echipamente, dotari | D7: F5 Form: Technical sheet for equipments, furniture and fixtures
B9: Nr. | C9: Specificatii tehnice impuse prin caietul de sarcini | D9: Technical specifications imposed by specification conditions - techincal notes | E9: Corespondenta propunerii tehnice cu specificatiile tehnice impuse prin caietul de sarcini / Correspondence of the technical proposal with the technical specifications imposed by the specification conditions | F9: Furnizor/Producator Provider/Manufacturer
B10: 0 | C10: 1 | D10: 1 | E10: 2 | F10: 3
B11: Fisa tehnica nr. 42 Utilajul, echipamentul tehnologic: Unitate de dozare pentru clor pentru sistem de recirculare bazine apa | D11: Technical sheet no. 42 Machinery, equipment: Dosing unit for chlorine for recirculation system of potable water tanks
